Workbook

Sheet Лист 1
A1: Ценовой лист | C1: Остатки | D1: от 26.01.2026
A2: К договору поставки | C2: Остатки | D2: от 26.01.2027
A3: Тип | C3: Основной
A4: Цены действуют | C4: с 01.02.2026 | D4: по 01.09.2027
A5: Комментарий для себя
A6: Сообщение покупателю | C6: Актуальные остатки 29.06
C8: Наименование | D8: ИНН | E8: КПП | F8: GLN
A9: Покупатель: | C9: ТС «ВсеИнструменты.ру» | D9: 7722753969 | E9: 997750001 | F9: 4607977269995
A10: Поставщик: | C10: ООО "ШАЙН СИСТЕМС" | D10: 5407951552 | E10: 540501001 | F10: 4652245476995
A12: № | B12: Штрих-код | C12: Наименование | D12: Код сети | E12: Артикул | F12: Суббренд | G12: Функциональное название | H12: Наименование производителя | I12: Новая цена без НДС | J12: Ставка НДС | K12: Действующая цена с НДС | L12: Новая цена с НДС | M12: Валюта новой цены | N12: РРЦ | O12: Валюта РРЦ | P12: МОЦ | Q12: Валюта МОЦ | R12: Ед. изм. | S12: Количество в упаковке | T12: Срок годности | V12: Категория товаров | W12: Ширина | X12: Высота | Y12: Глубина | Z12: Ед. изм. размеров | AA12: GLN склада | AB12: Остаток на складе | AC12: Срок изготовления, дней | AD12: Признак опасности | AE12: Квант поставки | AF12: Страна производства | AG12: Вес брутто, кг | AH12: Код ТН ВЭД | AI12: Данные о сертификатах и декларациях заполняются на вкладке "Сертификаты и декларации"
A13: 1 | B13: 2037427400104 | C13: Shine systems Glass Towel - безворсовая микрофибра для стекол 4040 см SS902 | D13: SS902 | E13: SS902 | F13: Shine Systems | H13: Shine systems Glass Towel - безворсовая микрофибра для стекол 4040 см SS902 | I13: 82.786885 | J13: 0.22 | K13: 101 | L13: 101 | M13: ₽ | N13: 150 | O13: ₽ | S13: 1 | W13: 400 | X13: 400 | Y13: 1 | Z13: мм | AB13: =_xlfn.XLOOKUP(D13,nomen!A:A,nomen!C:C,0) -> 1467 | AF13: Россия | AG13: 0.05
A14: 2 | B14: 2038480134739 | C14: Shine systems Универсальная микрофибра без оверлока edgeless 40x40см 400 гр/м2 (цвет серый) SS446 | D14: SS446 | E14: SS446 | F14: Shine Systems | H14: Shine systems Универсальная микрофибра без оверлока edgeless 40x40см 400 гр/м2 (цвет серый) SS446 | I14: 82.786885 | J14: 0.22 | K14: 101 | L14: 101 | M14: ₽ | N14: 150 | O14: ₽ | S14: 1 | W14: 220 | X14: 80 | Y14: 80 | Z14: мм | AB14: =_xlfn.XLOOKUP(E14,nomen!A:A,nomen!C:C,0) -> 1430 | AF14: Россия | AG14: 0.02
A15: 3 | B15: 2000000016801 | C15: Shine systems Edgeless Towel – универсальная микрофибра без оверлока 4040см, 400гр/м2 SS996 | D15: SS996 | E15: SS996 | F15: Shine Systems | H15: Shine systems Edgeless Towel – универсальная микрофибра без оверлока 4040см, 400гр/м2 SS996 | I15: 82.786885 | J15: 0.22 | K15: 101 | L15: 101 | M15: ₽ | N15: 150 | O15: ₽ | S15: 1 | W15: 215 | X15: 215 | Y15: 20 | Z15: мм | AB15: =_xlfn.XLOOKUP(E15,nomen!A:A,nomen!C:C,0) -> 925 | AF15: Россия | AG15: 0.07
A16: 4 | B16: 2037427399323 | C16: Shine Systems FastQuartz быстрое супергидрофобное покрытие, 750 мл SS765 | D16: SS765 | E16: SS765 | F16: Shine Systems | H16: Shine Systems FastQuartz быстрое супергидрофобное покрытие, 750 мл SS765 | I16: 459.01639 | J16: 0.22 | K16: 560 | L16: 560 | M16: ₽ | N16: 890 | O16: ₽ | S16: 1 | W16: 70 | X16: 70 | Y16: 230 | Z16: мм | AB16: =_xlfn.XLOOKUP(E16,nomen!A:A,nomen!C:C,0) -> 725 | AF16: Россия | AG16: 0.8
A17: 5 | B17: 2037427399569 | C17: Shine systems Heavy Duty Trigger - распрыскиватель химически стойкий SS816 | D17: SS816 | E17: SS816 | F17: Shine Systems | H17: Shine systems Heavy Duty Trigger - распрыскиватель химически стойкий SS816 | I17: 104.09836 | J17: 0.22 | K17: 127 | L17: 127 | M17: ₽ | N17: 190 | O17: ₽ | S17: 1 | W17: 58 | X17: 32 | Y17: 58 | Z17: мм | AB17: =_xlfn.XLOOKUP(E17,nomen!A:A,nomen!C:C,0) -> 1199 | AF17: Россия | AG17: 0.022
A18: 6 | B18: 2037427400135 | C18: Shine Systems IronOFF бескислотный очиститель дисков с индикатором, 750 мл SS907 | D18: SS907 | E18: SS907 | F18: Shine Systems | H18: Shine Systems IronOFF бескислотный очиститель дисков с индикатором, 750 мл SS907 | I18: 304.91803 | J18: 0.22 | K18: 372 | L18: 372 | M18: ₽ | N18: 590 | O18: ₽ | S18: 1 | W18: 70 | X18: 70 | Y18: 210 | Z18: мм | AB18: =_xlfn.XLOOKUP(E18,nomen!A:A,nomen!C:C,0) -> 749 | AF18: Россия | AG18: 8
A19: 7 | B19: 2037427400142 | C19: Shine Systems IPA антисиликон обезжириватель на спиртовой основе, 750 мл SS912 | D19: SS912 | E19: SS912 | F19: Shine Systems | H19: Shine Systems IPA антисиликон обезжириватель на спиртовой основе, 750 мл SS912 | I19: 181.96721 | J19: 0.22 | K19: 222 | L19: 222 | M19: ₽ | N19: 350 | O19: ₽ | S19: 1 | W19: 70 | X19: 70 | Y19: 225 | Z19: мм | AB19: =_xlfn.XLOOKUP(E19,nomen!A:A,nomen!C:C,0) -> 399 | AF19: Россия | AG19: 0.8
A20: 8 | B20: 4673746970348 | C20: Shine systems Black line perfectglass - бесспиртовой стеклоочиститель, 400 мл SSBL983 | D20: SSBL983 | E20: SSBL983 | F20: Shine Systems | H20: Shine systems Black line perfectglass - бесспиртовой стеклоочиститель, 400 мл SSBL983 | I20: 98.360656 | J20: 0.22 | K20: 120 | L20: 120 | M20: ₽ | N20: 190 | O20: ₽ | S20: 1 | W20: 220 | X20: 80 | Y20: 80 | Z20: мм | AB20: =_xlfn.XLOOKUP(E20,nomen!A:A,nomen!C:C,0) -> 442 | AF20: Россия | AG20: 0.4
A21: 9 | B21: 2037427399637 | C21: Shine Systems GlossyGlass экспресс очиститель стекол, 5 л SS827 | D21: SS827 | E21: SS827 | F21: Shine Systems | H21: Shine Systems GlossyGlass экспресс очиститель стекол, 5 л SS827 | I21: 284.42623 | J21: 0.22 | K21: 347 | L21: 347 | M21: ₽ | N21: 550 | O21: ₽ | S21: 1 | W21: 170 | X21: 130 | Y21: 250 | Z21: мм | AB21: =_xlfn.XLOOKUP(E21,nomen!A:A,nomen!C:C,0) -> 86 | AF21: Россия | AG21: 5
A22: 10 | B22: 2037427399460 | C22: Shine systems Easy Dry Plus Towel - супервпитывающая микрофибра для сушки кузова 5060см, 600гр/м2 SS800 | D22: SS800 | E22: SS800 | F22: Shine Systems | H22: Shine systems Easy Dry Plus Towel - супервпитывающая микрофибра для сушки кузова 5060см, 600гр/м2 SS800 | I22: 213.11475 | J22: 0.22 | K22: 260 | L22: 260 | M22: ₽ | N22: 390 | O22: ₽ | S22: 1 | W22: 255 | X22: 35 | Y22: 255 | Z22: мм | AB22: =_xlfn.XLOOKUP(E22,nomen!A:A,nomen!C:C,0) -> 1087 | AF22: Россия | AG22: 0.192
A23: 11 | B23: 2037427399972 | C23: Shine Systems ResinOFF очиститель древесных смол, 750 мл SS876 | D23: SS876 | E23: SS876 | F23: Shine Systems | H23: Shine Systems ResinOFF очиститель древесных смол, 750 мл SS876 | I23: 200.81967 | J23: 0.22 | K23: 245 | L23: 245 | M23: ₽ | N23: 390 | O23: ₽ | S23: 1 | W23: 70 | X23: 70 | Y23: 210 | Z23: мм | AB23: =_xlfn.XLOOKUP(E23,nomen!A:A,nomen!C:C,0) -> 348 | AF23: Россия | AG23: 8
A24: 12 | B24: 2037427399583 | C24: Shine systems Wash Sponge - губка крупноячеистая для мойки кузова 20126см SS819 | D24: SS819 | E24: SS819 | F24: Shine Systems | H24: Shine systems Wash Sponge - губка крупноячеистая для мойки кузова 20126см SS819 | I24: 159.01639 | J24: 0.22 | K24: 194 | L24: 194 | M24: ₽ | N24: 290 | O24: ₽ | S24: 1 | W24: 290 | X24: 200 | Y24: 10 | Z24: мм | AB24: =_xlfn.XLOOKUP(E24,nomen!A:A,nomen!C:C,0) -> 3200 | AF24: Россия | AG24: 0.062
A25: 13 | B25: 2037427398548 | C25: Shine systems EasyFinish - мелкоабразивная полировальная паста, 200 мл SS585 | D25: SS585 | E25: SS585 | F25: Shine Systems | H25: Shine systems EasyFinish - мелкоабразивная полировальная паста, 200 мл SS585 | I25: 411.47541 | J25: 0.22 | K25: 502 | L25: 502 | M25: ₽ | N25: 690 | O25: ₽ | S25: 1 | W25: 45 | X25: 45 | Y25: 180 | Z25: мм | AB25: =_xlfn.XLOOKUP(E25,nomen!A:A,nomen!C:C,0) -> 0 | AF25: Россия | AG25: 0.209
A26: 14 | B26: 2037427399668 | C26: Shine Systems AntiGraffiti деликатный очиститель краски, клея, скотча, 750 мл SS830 | D26: SS830 | E26: SS830 | F26: Shine Systems | H26: Shine Systems AntiGraffiti деликатный очиститель краски, клея, скотча, 750 мл SS830 | I26: 439.34426 | J26: 0.22 | K26: 536 | L26: 536 | M26: ₽ | N26: 850 | O26: ₽ | S26: 1 | W26: 72 | X26: 72 | Y26: 220 | Z26: мм | AB26: =_xlfn.XLOOKUP(E26,nomen!A:A,nomen!C:C,0) -> 32 | AF26: Россия | AG26: 0.8
A27: 15 | B27: 2037427398593 | C27: Shine systems Glass Applicator - аппликатор для чистки стекла и хрома 654 см SS590 | D27: SS590 | E27: SS590 | F27: Shine Systems | H27: Shine systems Glass Applicator - аппликатор для чистки стекла и хрома 654 см SS590 | I27: 98.360656 | J27: 0.22 | K27: 120 | L27: 120 | M27: ₽ | N27: 180 | O27: ₽ | S27: 1 | W27: 50 | X27: 40 | Y27: 50 | Z27: мм | AB27: =_xlfn.XLOOKUP(E27,nomen!A:A,nomen!C:C,0) -> 10959 | AF27: Россия | AG27: 0.014
A28: 16 | B28: 2037427398494 | C28: Shine systems AbrasivePrep - абразивный очиститель стекла, 200 мл SS579 | D28: SS579 | E28: SS579 | F28: Shine Systems | H28: Shine systems AbrasivePrep - абразивный очиститель стекла, 200 мл SS579 | I28: 305.7377 | J28: 0.22 | K28: 373 | L28: 373 | M28: ₽ | N28: 590 | O28: ₽ | S28: 1 | W28: 160 | X28: 45 | Y28: 160 | Z28: мм | AB28: =_xlfn.XLOOKUP(E28,nomen!A:A,nomen!C:C,0) -> 998 | AF28: Россия | AG28: 0.265
A29: 17 | B29: 2037510035237 | C29: Shine systems Bucket + Filter - ведро для мойки автомобиля c сепаратором, 20 л SS457 | D29: SS457 | E29: SS457 | F29: Shine Systems | H29: Shine systems Bucket + Filter - ведро для мойки автомобиля c сепаратором, 20 л SS457 | I29: 975.40984 | J29: 0.22 | K29: 1190 | L29: 1190 | M29: ₽ | N29: 1790 | O29: ₽ | S29: 1 | W29: 300 | X29: 300 | Y29: 380 | Z29: мм | AB29: =_xlfn.XLOOKUP(E29,nomen!A:A,nomen!C:C,0) -> 0 | AF29: Россия | AG29: 0.859
A30: 18 | B30: 2038480134722 | C30: Shine systems Микрофибра для сушки кузова 50x80см easy dry max SS587 | D30: SS587 | E30: SS587 | F30: Shine Systems | H30: Shine systems Микрофибра для сушки кузова 50x80см easy dry max SS587 | I30: 283.60656 | J30: 0.22 | K30: 346 | L30: 346 | M30: ₽ | N30: 520 | O30: ₽ | S30: 1 | W30: 80 | X30: 50 | Y30: 30 | Z30: мм | AB30: =_xlfn.XLOOKUP(E30,nomen!A:A,nomen!C:C,0) -> 4935 | AF30: Россия | AG30: 0.1
A31: 19 | B31: 2037427398531 | C31: Shine systems FastPolish - среднеабразивная полировальная паста, 200 мл SS584 | D31: SS584 | E31: SS584 | F31: Shine Systems | H31: Shine systems FastPolish - среднеабразивная полировальная паста, 200 мл SS584 | I31: 531.14754 | J31: 0.22 | K31: 648 | L31: 648 | M31: ₽ | N31: 890 | O31: ₽ | S31: 1 | W31: 45 | X31: 45 | Y31: 180 | Z31: мм | AB31: =_xlfn.XLOOKUP(E31,nomen!A:A,nomen!C:C,0) -> 0 | AF31: Россия | AG31: 0.226
A32: 20 | B32: 2037427400395 | C32: Shine systems Magic Sponge - губка меламиновая 963 см, 4шт. SS961 | D32: SS961 | E32: SS961 | F32: Shine Systems | H32: Shine systems Magic Sponge - губка меламиновая 963 см, 4шт. SS961 | I32: 159.01639 | J32: 0.22 | K32: 194 | L32: 194 | M32: ₽ | N32: 290 | O32: ₽ | S32: 1 | W32: 120 | X32: 63 | Y32: 120 | Z32: мм | AB32: =_xlfn.XLOOKUP(E32,nomen!A:A,nomen!C:C,0) -> 1477 | AF32: Россия | AG32: 0.024
... A37: 25 | B37: 2037427398517 | C37: Shine systems Terry Towel - универсальная микрофибра без оверлока 4040см, 6 шт SS582 | D37: SS582 | E37: SS582 | F37: Shine Systems | H37: Shine systems Terry Towel - универсальная микрофибра без оверлока 4040см, 6 шт SS582 | I37: 322.13115 | J37: 0.22 | K37: 393 | L37: 393 | M37: ₽ | N37: 590 | O37: ₽ | S37: 1 | W37: 215 | X37: 215 | Y37: 60 | Z37: мм | AB37: =_xlfn.XLOOKUP(E37,nomen!A:A,nomen!C:C,0) -> 551 | AF37: Россия | AG37: 0.252
A38: 26 | B38: 4673746973011 | C38: Shine systems Матовый полироль для пластика салона AirLine PolishMatt, 400 мл SS430 | D38: SS430 | E38: SS430 | F38: Shine Systems | H38: Shine systems Матовый полироль для пластика салона AirLine PolishMatt, 400 мл SS430 | I38: 290.98361 | J38: 0.22 | K38: 355 | L38: 355 | M38: ₽ | N38: 490 | O38: ₽ | S38: 1 | W38: 220 | X38: 80 | Y38: 80 | Z38: мм | AB38: =_xlfn.XLOOKUP(E38,nomen!A:A,nomen!C:C,0) -> 20 | AF38: Россия | AG38: 0.3
A39: 27 | B39: 4673746972144 | C39: Shine systems Гибридный полировальный круг 155 мм Hybrid Pad Shine Systems SS533 | D39: SS533 | E39: SS533 | F39: Shine Systems | H39: Shine systems Гибридный полировальный круг 155 мм Hybrid Pad Shine Systems SS533 | I39: 591.80328 | J39: 0.22 | K39: 722 | L39: 722 | M39: ₽ | N39: 1090 | O39: ₽ | S39: 1 | W39: 100 | X39: 100 | Y39: 50 | Z39: мм | AB39: =_xlfn.XLOOKUP(E39,nomen!A:A,nomen!C:C,0) -> 256 | AF39: Россия | AG39: 0.2
A40: 28 | B40: 4673746970454 | C40: Shine systems Чернитель для резины матовый Shine Systems BlackStar Matt, 750 мл SS918 | D40: SS918 | E40: SS918 | F40: Shine Systems | H40: Shine systems Чернитель для резины матовый Shine Systems BlackStar Matt, 750 мл SS918 | I40: 386.06557 | J40: 0.22 | K40: 471 | L40: 471 | M40: ₽ | N40: 750 | O40: ₽ | S40: 1 | W40: 70 | X40: 70 | Y40: 210 | Z40: мм | AB40: =_xlfn.XLOOKUP(E40,nomen!A:A,nomen!C:C,0) -> 379 | AF40: Россия | AG40: 0.8
A41: 29 | B41: 4652245476742 | C41: Shine systems Универсальное средство для химчистки Shine Systems InteriorCleaner, 750 мл SS865 | D41: SS865 | E41: SS865 | F41: Shine Systems | H41: Shine systems Универсальное средство для химчистки Shine Systems InteriorCleaner, 750 мл SS865 | I41: 200.81967 | J41: 0.22 | K41: 245 | L41: 245 | M41: ₽ | N41: 390 | O41: ₽ | S41: 1 | W41: 70 | X41: 70 | Y41: 210 | Z41: мм | AB41: =_xlfn.XLOOKUP(E41,nomen!A:A,nomen!C:C,0) -> 848 | AF41: Россия | AG41: 0.9
A42: 30 | B42: 2038480134715 | C42: Shine systems Easy dry double max - двуслойная микрофибра для сушки кузова 50x80см, 1200гр/м2 SS443 | D42: SS443 | E42: SS443 | F42: Shine Systems | H42: Shine systems Easy dry double max - двуслойная микрофибра для сушки кузова 50x80см, 1200гр/м2 SS443 | I42: 649.18033 | J42: 0.22 | K42: 792 | L42: 792 | M42: ₽ | N42: 1190 | O42: ₽ | S42: 1 | W42: 45 | X42: 45 | Y42: 180 | Z42: мм | AB42: =_xlfn.XLOOKUP(E42,nomen!A:A,nomen!C:C,0) -> 165 | AF42: Россия | AG42: 0.5
A43: 31 | B43: 2037427399361 | C43: Shine Systems PinkFoam активный шампунь для бесконтактной мойки, 5 л SS775 | D43: SS775 | E43: SS775 | F43: Shine Systems | H43: Shine Systems PinkFoam активный шампунь для бесконтактной мойки, 5 л SS775 | I43: 1068.0328 | J43: 0.22 | K43: 1303 | L43: 1303 | M43: ₽ | N43: 1790 | O43: ₽ | S43: 1 | W43: 170 | X43: 130 | Y43: 250 | Z43: мм | AB43: =_xlfn.XLOOKUP(E43,nomen!A:A,nomen!C:C,0) -> 74 | AF43: Россия | AG43: 5
A44: 32 | B44: 4673746971048 | C44: Shine systems Очиститель дисков с индикатором Shine Systems IronOFF Gel, 750 мл SS753 | D44: SS753 | E44: SS753 | F44: Shine Systems | H44: Shine systems Очиститель дисков с индикатором Shine Systems IronOFF Gel, 750 мл SS753 | I44: 304.09836 | J44: 0.22 | K44: 371 | L44: 371 | M44: ₽ | N44: 590 | O44: ₽ | S44: 1 | W44: 70 | X44: 70 | Y44: 210 | Z44: мм | AB44: =_xlfn.XLOOKUP(E44,nomen!A:A,nomen!C:C,0) -> 588 | AF44: Россия | AG44: 0.9
A45: 33 | B45: 2037427400111 | C45: Shine Systems GlassCleaner универсальный очиститель стекол, 750 мл SS903 | D45: SS903 | E45: SS903 | F45: Shine Systems | H45: Shine Systems GlassCleaner универсальный очиститель стекол, 750 мл SS903 | I45: 129.5082 | J45: 0.22 | K45: 158 | L45: 158 | M45: ₽ | N45: 250 | O45: ₽ | S45: 1 | W45: 70 | X45: 70 | Y45: 230 | Z45: мм | AB45: =_xlfn.XLOOKUP(E45,nomen!A:A,nomen!C:C,0) -> 566 | AF45: Россия | AG45: 0.8
A46: 34 | B46: 2000000000817 | C46: Shine Systems MotorCleaner гель диэлектрик для мойки двигателя, 750 мл SS807 | D46: SS807 | E46: SS807 | F46: Shine Systems | H46: Shine Systems MotorCleaner гель диэлектрик для мойки двигателя, 750 мл SS807 | I46: 439.34426 | J46: 0.22 | K46: 536 | L46: 536 | M46: ₽ | N46: 850 | O46: ₽ | S46: 1 | W46: 70 | X46: 70 | Y46: 210 | Z46: мм | AB46: =_xlfn.XLOOKUP(E46,nomen!A:A,nomen!C:C,0) -> 879 | AF46: Россия | AG46: 8
...

Sheet Сертификаты и декларации
A1: № | B1: Штрих-код товарной позиции | C1: Номер сертификата или декларации соответствия | D1: Дата регистрации сертификата или декларации соответствия | E1: Дата окончания действия сертификата или декларации соответствия | F1: Ссылка на сертификат или декларацию соответствия в реестре сертификатов и деклараций соответствия | H1: Укажите данные о сертификатах и декларациях. В одной строке должен быть один сертификат или декларация.

Sheet Страны
A1: Страны
A2: Абхазия
A3: Австралия
A4: Австрия
A5: Азербайджан
A6: Албания
A7: Алжир
A8: Американское Самоа
A9: Ангилья
A10: Ангола
A11: Андорра
A12: Антарктида
... A252: Европейский союз

Sheet Единицы измерения
A1: Срок годности
A2: мес
A3: нед
A4: сут, дн
A5: ч

Sheet nomen
A2: SS590 | B2: Shine Systems Glass Applicator - аппликатор для чистки стекла и хрома 6*5*4 см | C2: 10959
A3: SS483 | B3: Shine Systems пакет 38х45 см черный | C3: 6089
A4: SS288 | B4: Shine Systems Waffle Towel - вафельная микрофибра, 40*40см | C4: 5971
A5: SS587 | B5: Shine Systems Easy Dry Max Towel - супервпитывающая микрофибра для сушки кузова 50*80 см | C5: 4935
A6: SS972 | B6: Shine Systems Velvet Towel - вельветовая микрофибра без оверлока, 40*40см | C6: 3995
A7: SS811 | B7: Shine Systems Tire Applicator - аппликатор для чернения резины и пластика | C7: 3796
A8: SS819 | B8: Shine Systems Wash Sponge - губка крупноячеистая для мойки кузова 20*12*6см | C8: 3200
A9: SS410 | B9: Shine Systems Coating Sponge - аппликатор с прорезью для керамики 8*4,5*2 см | C9: 2949
A10: SS485 | B10: Shine Systems Scrab Towel - микрофибра-скраб для химчистки 40*40см | C10: 2935
A11: SS873 | B11: Shine Systems Lint-Free Towel - безворсовая универсальная микрофибра стрейч 40*40 см | C11: 2889
A12: SS884 | B12: Shine Systems Buffing Towel - микрофибра для располировки составов 40*40см | C12: 2747
A13: SS626 | B13: Shine Systems Standart Trigger - распрыскиватель дисперсионный | C13: 2479
... A30: SS310 | B30: Shine Systems Perl Towel - микрофибра с двойным плетением без оверлока 40*40см, 350гр/м2, 3 шт | C30: 1439
B31: Крышка твист топ (пуш-пулл винтовой) 24 | C31: 1430
A32: SS446 | B32: Shine Systems Edgeless Towel Gray - универсальная микрофибра без оверлока 40*40см, 400гр/м2, серая | C32: 1430
A33: SS560 | B33: Shine Systems DA Foam Pad Yellow - полировальный круг антиголограммный желтый, 130 мм | C33: 1344
A34: SS625 | B34: Shine Systems Foam Trigger - распрыскиватель пенный | C34: 1295
A35: SS163 | B35: Shine Systems TireTouch - кисть для ухода за резиной | C35: 1281
A36: SS518 | B36: Shine Systems AirLine SiliconeSpray - универсальная силиконовая смазка, 400 мл | C36: 1261
A37: SS816 | B37: Shine Systems Solvent Trigger (NBR) - профессиональный распрыскиватель для сольвентов и слабощелочных (3-9pH) составов | C37: 1199
A38: SS737 | B38: Shine Systems Ultra Soft Brush - ультрамягкая кисть для детейлинга | C38: 1196
A39: SS548 | B39: Shine Systems RO Foam Pad Yellow - полировальный круг полутвердый желтый, 130 мм | C39: 1195
A40: SS642 | B40: Shine Systems Utility Towel - универсальная микрофибра 30*30см, 10шт | C40: 1161
A41: SS800 | B41: Shine Systems Easy Dry Towel - супервпитывающая микрофибра для сушки кузова 50*60см, 600гр/м2 | C41: 1087
A42: SS534 | B42: Shine Systems Hybrid Pad - гибридный полировальный круг, 130 мм | C42: 1060
A43: SS549 | B43: Shine Systems RO Foam Pad Green - полировальный круг твердый зеленый, 130 мм | C43: 1053
... A48: SS719 | B48: Shine Systems PinkFoam - активный шампунь для бесконтактной мойки, 750 мл | C48: 971
B49: Shine Systems Uni Dry Towel - универсальная супервпитывающая микрофибра 40*40см, 500гр/м2 | C49: 954
A50: SS295 | B50: Shine Systems Masking Tape - малярная лента синяя 18мм*50м | C50: 952
B51: Shine Systems Rim Sponge - губка для мойки дисков и порогов | C51: 951
A52: SS542 | B52: Shine Systems Stripy Wool Pad - полировальный круг из стриженого меха, 130 мм | C52: 947
A53: SS418 | B53: Shine Systems Coating Suede - замша для нанесения керамики 10*10см, 10 шт | C53: 941
A54: SS342 | B54: Shine Systems Masking Tape - малярная лента зеленая 18мм*50м | C54: 939
A55: SS305 | B55: Shine Systems Masking Tape - малярная лента красная 18мм*50м | C55: 929
A56: SS996 | B56: Shine Systems Edgeless Towel Blue - универсальная микрофибра без оверлока 40*40см, 400гр/м2, голубая | C56: 925
B57: Shine Systems этикетка WipeOFF | C57: 904
A58: SS558 | B58: Shine Systems DA Foam Pad Orange - полировальный круг мягкий оранжевый, 130 мм | C58: 901
A59: SS530 | B59: Shine Systems Clay Bar - полировальная глина, 100 гр | C59: 884
A60: SS807 | B60: Shine Systems MotorCleaner - гель-диэлектрик для мойки двигателя, 750 мл | C60: 879
A61: SS554 | B61: Shine Systems DA Foam Pad Yellow - полировальный круг антиголограммный желтый, 155 мм | C61: 869
...
